Workbook

Sheet How To Use
B2: Automated Recruitment Tracker
B3: You only type in the cream / dark-navy-header columns. Everything in light-blue cells (teal headers) is calculated automatically.
B5: 1. Requisitions — add each open role (Req ID, Role, Openings, Open & Target dates). Candidate counts, fill %, days open and status (Open / Overdue / No Pipeline / Filled) update themselves.
B6: 2. Candidates — add one row per candidate. Pick the Req ID from the dropdown; Role and Hiring Manager fill in automatically. Candidate ID is generated.
B7: 3. When a candidate moves, change 'Current Stage' and set 'Stage Updated On' to today (Ctrl + ; ). The sheet recalculates days in stage, SLA status, next action, hike %, time-to-offer and time-to-hire.
B8: 4. For Rejected / Withdrawn candidates, fill 'Dropped At Stage' (cell turns amber until you do) so the funnel stays accurate.
B9: 5. Dashboard — KPI tiles, funnel conversion, source effectiveness, recruiter performance, monthly trend and requisition health. Nothing to edit; it refreshes on open.
B10: 6. Lists — change stages, SLA days, next-action text, sources, recruiters, departments and locations. Every dropdown and rule follows these settings.
B12: Automations built in
B13: • Auto Candidate ID, Role / Hiring Manager lookup, duplicate email & Req ID blocking, dropdowns and date validation on every input.
B14: • SLA engine: flags candidates sitting in a stage longer than its SLA (red 'BREACH'). Next Action tells the recruiter what to do.
B15: • Expected joining date = Offer date + notice period; hike % highlighted amber when above 40%.
... B23: • This copy contains DEMO data (6 reqs, 40 candidates). Use Recruitment_Tracker_Template.xlsx for a clean start.

Sheet Dashboard
B2: Recruitment Dashboard
B3: ="Auto-refreshed • Report as of "&TEXT(TODAY(),"dd-mmm-yyyy") -> Auto-refreshed • Report as of 15-Oct-2026
B5: Total Candidates | D5: Active Pipeline | G5: Offers Made | I5: Joined
B6: =COUNTIF(Candidates!$B$2:$B$501,"?*") -> 40 | D6: =COUNTIF(Candidates!$M$2:$M$501,"Active") -> 27 | G6: =COUNTIF(Candidates!$T$2:$T$501,"<>") -> 16 | I6: =COUNTIF(Candidates!$K$2:$K$501,"Joined") -> 6
B8: Offer Acceptance % | D8: Avg Time to Hire (d) | G8: Avg Time to Offer (d) | I8: SLA Breaches
B9: =IFERROR((COUNTIF(Candidates!$K$2:$K$501,"Offer Accepted")+COUNTIF(Candidates!$K$2:$K$501,"Joined"))/(COUNTIF(Candidates!$K$2:$K$501,"Offer Accepted")+COUNTIF(Candidates!$K$2:$K$501,"Joined")+COUNTIF(Candidates!$K$2:$K$501,"Offer Declined")),0) -> 0.83333333 | D9: =IFERROR(AVERAGE(Candidates!$AD$2:$AD$501),0) -> 54.333333 | G9: =IFERROR(AVERAGE(Candidates!$AC$2:$AC$501),0) -> 23.875 | I9: =COUNTIF(Candidates!$Z$2:$Z$501,"BREACH") -> 14
B11: Open Requisitions | D11: Openings Left | G11: Overdue Reqs | I11: Avg Hike Asked
B12: =COUNTIF(Requisitions!$S$2:$S$101,"Open")+COUNTIF(Requisitions!$S$2:$S$101,"Overdue")+COUNTIF(Requisitions!$S$2:$S$101,"No Pipeline") -> 3 | D12: =SUM(Requisitions!$O$2:$O$101) -> 5 | G12: =COUNTIF(Requisitions!$S$2:$S$101,"Overdue") -> 1 | I12: =IFERROR(AVERAGE(Candidates!$V$2:$V$501),0) -> 0.37256267
B15: Hiring Funnel | G15: Current Stage Snapshot
B16: Stage | C16: Reached | D16: % of Total | E16: Step Conv. | G16: Stage | H16: Candidates | I16: SLA Breach
B17: Sourced | C17: =COUNTIF(Candidates!$AE$2:$AE$501,">="&INDEX(Lists!$B$4:$B$14,MATCH(B17,Lists!$A$4:$A$14,0))) -> 40 | D17: =IFERROR(C17/$C$17,0) -> 1 | G17: Sourced | H17: =COUNTIF(Candidates!$K$2:$K$501,G17) -> 4 | I17: =COUNTIFS(Candidates!$K$2:$K$501,G17,Candidates!$Z$2:$Z$501,"BREACH") -> 2
B18: Screening | C18: =COUNTIF(Candidates!$AE$2:$AE$501,">="&INDEX(Lists!$B$4:$B$14,MATCH(B18,Lists!$A$4:$A$14,0))) -> 34 | D18: =IFERROR(C18/$C$17,0) -> 0.85 | E18: =IFERROR(C18/C17,0) -> 0.85 | G18: Screening | H18: =COUNTIF(Candidates!$K$2:$K$501,G18) -> 4 | I18: =COUNTIFS(Candidates!$K$2:$K$501,G18,Candidates!$Z$2:$Z$501,"BREACH") -> 3
B19: Tech Round 1 | C19: =COUNTIF(Candidates!$AE$2:$AE$501,">="&INDEX(Lists!$B$4:$B$14,MATCH(B19,Lists!$A$4:$A$14,0))) -> 30 | D19: =IFERROR(C19/$C$17,0) -> 0.75 | E19: =IFERROR(C19/C18,0) -> 0.88235294 | G19: Tech Round 1 | H19: =COUNTIF(Candidates!$K$2:$K$501,G19) -> 5 | I19: =COUNTIFS(Candidates!$K$2:$K$501,G19,Candidates!$Z$2:$Z$501,"BREACH") -> 0
B20: Tech Round 2 | C20: =COUNTIF(Candidates!$AE$2:$AE$501,">="&INDEX(Lists!$B$4:$B$14,MATCH(B20,Lists!$A$4:$A$14,0))) -> 24 | D20: =IFERROR(C20/$C$17,0) -> 0.6 | E20: =IFERROR(C20/C19,0) -> 0.8 | G20: Tech Round 2 | H20: =COUNTIF(Candidates!$K$2:$K$501,G20) -> 2 | I20: =COUNTIFS(Candidates!$K$2:$K$501,G20,Candidates!$Z$2:$Z$501,"BREACH") -> 0
B21: HR Round | C21: =COUNTIF(Candidates!$AE$2:$AE$501,">="&INDEX(Lists!$B$4:$B$14,MATCH(B21,Lists!$A$4:$A$14,0))) -> 20 | D21: =IFERROR(C21/$C$17,0) -> 0.5 | E21: =IFERROR(C21/C20,0) -> 0.83333333 | G21: HR Round | H21: =COUNTIF(Candidates!$K$2:$K$501,G21) -> 4 | I21: =COUNTIFS(Candidates!$K$2:$K$501,G21,Candidates!$Z$2:$Z$501,"BREACH") -> 3
B22: Offered | C22: =COUNTIF(Candidates!$AE$2:$AE$501,">="&INDEX(Lists!$B$4:$B$14,MATCH(B22,Lists!$A$4:$A$14,0))) -> 16 | D22: =IFERROR(C22/$C$17,0) -> 0.4 | E22: =IFERROR(C22/C21,0) -> 0.8 | G22: Offered | H22: =COUNTIF(Candidates!$K$2:$K$501,G22) -> 4 | I22: =COUNTIFS(Candidates!$K$2:$K$501,G22,Candidates!$Z$2:$Z$501,"BREACH") -> 4
B23: Offer Accepted | C23: =COUNTIF(Candidates!$AE$2:$AE$501,">="&INDEX(Lists!$B$4:$B$14,MATCH(B23,Lists!$A$4:$A$14,0))) -> 10 | D23: =IFERROR(C23/$C$17,0) -> 0.25 | E23: =IFERROR(C23/C22,0) -> 0.625 | G23: Offer Accepted | H23: =COUNTIF(Candidates!$K$2:$K$501,G23) -> 4 | I23: =COUNTIFS(Candidates!$K$2:$K$501,G23,Candidates!$Z$2:$Z$501,"BREACH") -> 2
B24: Joined | C24: =COUNTIF(Candidates!$AE$2:$AE$501,">="&INDEX(Lists!$B$4:$B$14,MATCH(B24,Lists!$A$4:$A$14,0))) -> 6 | D24: =IFERROR(C24/$C$17,0) -> 0.15 | E24: =IFERROR(C24/C23,0) -> 0.6 | G24: Joined | H24: =COUNTIF(Candidates!$K$2:$K$501,G24) -> 6 | I24: =COUNTIFS(Candidates!$K$2:$K$501,G24,Candidates!$Z$2:$Z$501,"BREACH") -> 0
G25: Offer Declined | H25: =COUNTIF(Candidates!$K$2:$K$501,G25) -> 2 | I25: =COUNTIFS(Candidates!$K$2:$K$501,G25,Candidates!$Z$2:$Z$501,"BREACH") -> 0
G26: Rejected | H26: =COUNTIF(Candidates!$K$2:$K$501,G26) -> 4 | I26: =COUNTIFS(Candidates!$K$2:$K$501,G26,Candidates!$Z$2:$Z$501,"BREACH") -> 0
G27: Withdrawn | H27: =COUNTIF(Candidates!$K$2:$K$501,G27) -> 1 | I27: =COUNTIFS(Candidates!$K$2:$K$501,G27,Candidates!$Z$2:$Z$501,"BREACH") -> 0
B30: Source Effectiveness | G30: Recruiter Performance
B31: Source | C31: Candidates | D31: Hires | E31: Hire Rate | G31: Recruiter | H31: Candidates | I31: Active | J31: Offers | K31: Joined
B32: =Lists!G4 -> LinkedIn | C32: =IF(B32="","",COUNTIF(Candidates!$H$2:$H$501,B32)) -> 7 | D32: =IF(B32="","",COUNTIFS(Candidates!$H$2:$H$501,B32,Candidates!$K$2:$K$501,"Joined")) -> 1 | E32: =IF(B32="","",IFERROR(D32/C32,0)) -> 0.14285714 | G32: =Lists!H4 -> Pravin Christo | H32: =IF(G32="","",COUNTIF(Candidates!$I$2:$I$501,G32)) -> 14 | I32: =IF(G32="","",COUNTIFS(Candidates!$I$2:$I$501,G32,Candidates!$M$2:$M$501,"Active")) -> 10 | J32: =IF(G32="","",COUNTIFS(Candidates!$I$2:$I$501,G32,Candidates!$T$2:$T$501,"<>")) -> 5 | K32: =IF(G32="","",COUNTIFS(Candidates!$I$2:$I$501,G32,Candidates!$K$2:$K$501,"Joined")) -> 2
B33: =Lists!G5 -> Naukri | C33: =IF(B33="","",COUNTIF(Candidates!$H$2:$H$501,B33)) -> 10 | D33: =IF(B33="","",COUNTIFS(Candidates!$H$2:$H$501,B33,Candidates!$K$2:$K$501,"Joined")) -> 1 | E33: =IF(B33="","",IFERROR(D33/C33,0)) -> 0.1 | G33: =Lists!H5 -> Recruiter 2 | H33: =IF(G33="","",COUNTIF(Candidates!$I$2:$I$501,G33)) -> 13 | I33: =IF(G33="","",COUNTIFS(Candidates!$I$2:$I$501,G33,Candidates!$M$2:$M$501,"Active")) -> 8 | J33: =IF(G33="","",COUNTIFS(Candidates!$I$2:$I$501,G33,Candidates!$T$2:$T$501,"<>")) -> 8 | K33: =IF(G33="","",COUNTIFS(Candidates!$I$2:$I$501,G33,Candidates!$K$2:$K$501,"Joined")) -> 3
B34: =Lists!G6 -> Referral | C34: =IF(B34="","",COUNTIF(Candidates!$H$2:$H$501,B34)) -> 5 | D34: =IF(B34="","",COUNTIFS(Candidates!$H$2:$H$501,B34,Candidates!$K$2:$K$501,"Joined")) -> 0 | E34: =IF(B34="","",IFERROR(D34/C34,0)) -> 0 | G34: =Lists!H6 -> Recruiter 3 | H34: =IF(G34="","",COUNTIF(Candidates!$I$2:$I$501,G34)) -> 13 | I34: =IF(G34="","",COUNTIFS(Candidates!$I$2:$I$501,G34,Candidates!$M$2:$M$501,"Active")) -> 9 | J34: =IF(G34="","",COUNTIFS(Candidates!$I$2:$I$501,G34,Candidates!$T$2:$T$501,"<>")) -> 3 | K34: =IF(G34="","",COUNTIFS(Candidates!$I$2:$I$501,G34,Candidates!$K$2:$K$501,"Joined")) -> 1
B35: =Lists!G7 -> Career Page | C35: =IF(B35="","",COUNTIF(Candidates!$H$2:$H$501,B35)) -> 4 | D35: =IF(B35="","",COUNTIFS(Candidates!$H$2:$H$501,B35,Candidates!$K$2:$K$501,"Joined")) -> 2 | E35: =IF(B35="","",IFERROR(D35/C35,0)) -> 0.5
B36: =Lists!G8 -> Indeed | C36: =IF(B36="","",COUNTIF(Candidates!$H$2:$H$501,B36)) -> 10 | D36: =IF(B36="","",COUNTIFS(Candidates!$H$2:$H$501,B36,Candidates!$K$2:$K$501,"Joined")) -> 1 | E36: =IF(B36="","",IFERROR(D36/C36,0)) -> 0.1
B37: =Lists!G9 -> Agency | C37: =IF(B37="","",COUNTIF(Candidates!$H$2:$H$501,B37)) -> 4 | D37: =IF(B37="","",COUNTIFS(Candidates!$H$2:$H$501,B37,Candidates!$K$2:$K$501,"Joined")) -> 1 | E37: =IF(B37="","",IFERROR(D37/C37,0)) -> 0.25
B38: =Lists!G10 -> Job Fair | C38: =IF(B38="","",COUNTIF(Candidates!$H$2:$H$501,B38)) -> 0 | D38: =IF(B38="","",COUNTIFS(Candidates!$H$2:$H$501,B38,Candidates!$K$2:$K$501,"Joined")) -> 0 | E38: =IF(B38="","",IFERROR(D38/C38,0)) -> 0
B39: =Lists!G11 -> Internal | C39: =IF(B39="","",COUNTIF(Candidates!$H$2:$H$501,B39)) -> 0 | D39: =IF(B39="","",COUNTIFS(Candidates!$H$2:$H$501,B39,Candidates!$K$2:$K$501,"Joined")) -> 0 | E39: =IF(B39="","",IFERROR(D39/C39,0)) -> 0
B42: Monthly Trend (current year) | G42: Requisition Health
B43: Month | C43: Applications | D43: Offers | E43: Joined | G43: Req Status | H43: Count
B44: =DATE(YEAR(TODAY()),1,1) -> 46023 | C44: =COUNTIFS(Candidates!$J$2:$J$501,">="&$B44,Candidates!$J$2:$J$501,"<"&EDATE($B44,1)) -> 0 | D44: =COUNTIFS(Candidates!$T$2:$T$501,">="&$B44,Candidates!$T$2:$T$501,"<"&EDATE($B44,1)) -> 0 | E44: =COUNTIFS(Candidates!$U$2:$U$501,">="&$B44,Candidates!$U$2:$U$501,"<"&EDATE($B44,1)) -> 0 | G44: Open | H44: =COUNTIF(Requisitions!$S$2:$S$101,G44) -> 2
B45: =DATE(YEAR(TODAY()),2,1) -> 46054 | C45: =COUNTIFS(Candidates!$J$2:$J$501,">="&$B45,Candidates!$J$2:$J$501,"<"&EDATE($B45,1)) -> 0 | D45: =COUNTIFS(Candidates!$T$2:$T$501,">="&$B45,Candidates!$T$2:$T$501,"<"&EDATE($B45,1)) -> 0 | E45: =COUNTIFS(Candidates!$U$2:$U$501,">="&$B45,Candidates!$U$2:$U$501,"<"&EDATE($B45,1)) -> 0 | G45: Overdue | H45: =COUNTIF(Requisitions!$S$2:$S$101,G45) -> 1
B46: =DATE(YEAR(TODAY()),3,1) -> 46082 | C46: =COUNTIFS(Candidates!$J$2:$J$501,">="&$B46,Candidates!$J$2:$J$501,"<"&EDATE($B46,1)) -> 0 | D46: =COUNTIFS(Candidates!$T$2:$T$501,">="&$B46,Candidates!$T$2:$T$501,"<"&EDATE($B46,1)) -> 0 | E46: =COUNTIFS(Candidates!$U$2:$U$501,">="&$B46,Candidates!$U$2:$U$501,"<"&EDATE($B46,1)) -> 0 | G46: No Pipeline | H46: =COUNTIF(Requisitions!$S$2:$S$101,G46) -> 0
B47: =DATE(YEAR(TODAY()),4,1) -> 46113 | C47: =COUNTIFS(Candidates!$J$2:$J$501,">="&$B47,Candidates!$J$2:$J$501,"<"&EDATE($B47,1)) -> 0 | D47: =COUNTIFS(Candidates!$T$2:$T$501,">="&$B47,Candidates!$T$2:$T$501,"<"&EDATE($B47,1)) -> 0 | E47: =COUNTIFS(Candidates!$U$2:$U$501,">="&$B47,Candidates!$U$2:$U$501,"<"&EDATE($B47,1)) -> 0 | G47: Filled | H47: =COUNTIF(Requisitions!$S$2:$S$101,G47) -> 3
B48: =DATE(YEAR(TODAY()),5,1) -> 46143 | C48: =COUNTIFS(Candidates!$J$2:$J$501,">="&$B48,Candidates!$J$2:$J$501,"<"&EDATE($B48,1)) -> 0 | D48: =COUNTIFS(Candidates!$T$2:$T$501,">="&$B48,Candidates!$T$2:$T$501,"<"&EDATE($B48,1)) -> 0 | E48: =COUNTIFS(Candidates!$U$2:$U$501,">="&$B48,Candidates!$U$2:$U$501,"<"&EDATE($B48,1)) -> 0
B49: =DATE(YEAR(TODAY()),6,1) -> 46174 | C49: =COUNTIFS(Candidates!$J$2:$J$501,">="&$B49,Candidates!$J$2:$J$501,"<"&EDATE($B49,1)) -> 6 | D49: =COUNTIFS(Candidates!$T$2:$T$501,">="&$B49,Candidates!$T$2:$T$501,"<"&EDATE($B49,1)) -> 0 | E49: =COUNTIFS(Candidates!$U$2:$U$501,">="&$B49,Candidates!$U$2:$U$501,"<"&EDATE($B49,1)) -> 0
B50: =DATE(YEAR(TODAY()),7,1) -> 46204 | C50: =COUNTIFS(Candidates!$J$2:$J$501,">="&$B50,Candidates!$J$2:$J$501,"<"&EDATE($B50,1)) -> 8 | D50: =COUNTIFS(Candidates!$T$2:$T$501,">="&$B50,Candidates!$T$2:$T$501,"<"&EDATE($B50,1)) -> 1 | E50: =COUNTIFS(Candidates!$U$2:$U$501,">="&$B50,Candidates!$U$2:$U$501,"<"&EDATE($B50,1)) -> 0
...

Sheet Requisitions
A1: Req ID | B1: Role | C1: Department | D1: Hiring Manager | E1: Location | F1: Openings | G1: Priority | H1: Recruiter | I1: Open Date | J1: Target Close Date | K1: Total Candidates | L1: Active Pipeline | M1: Offers Made | N1: Joined | O1: Openings Left | P1: Fill % | Q1: Days Open | R1: Days to Target | S1: Req Status
A2: REQ-101 | B2: QA Automation Engineer (Python) | C2: QA | D2: S. Raman | E2: Chennai | F2: 3 | G2: High | H2: Pravin Christo | I2: 46174 | J2: 46295 | K2: =IF($A2="","",COUNTIF(Candidates!$E$2:$E$501,$A2)) -> 7 | L2: =IF($A2="","",COUNTIFS(Candidates!$E$2:$E$501,$A2,Candidates!$M$2:$M$501,"Active")) -> 5 | M2: =IF($A2="","",COUNTIFS(Candidates!$E$2:$E$501,$A2,Candidates!$T$2:$T$501,"<>")) -> 1 | N2: =IF($A2="","",COUNTIFS(Candidates!$E$2:$E$501,$A2,Candidates!$K$2:$K$501,"Joined")) -> 0 | O2: =IF($A2="","",MAX($F2-$N2,0)) -> 3 | P2: =IF(OR($A2="",N($F2)=0),"",$N2/$F2) -> 0 | Q2: =IF(OR($A2="",$I2=""),"",TODAY()-$I2) -> 136 | R2: =IF(OR($A2="",$J2=""),"",$J2-TODAY()) -> -15 | S2: =IF($A2="","",IF($O2=0,"Filled",IF(AND($J2<>"",TODAY()>$J2),"Overdue",IF($L2=0,"No Pipeline","Open")))) -> Overdue
A3: REQ-102 | B3: Senior SDET | C3: QA | D3: M. Iyer | E3: Bangalore | F3: 2 | G3: High | H3: Pravin Christo | I3: 46213 | J3: 46326 | K3: =IF($A3="","",COUNTIF(Candidates!$E$2:$E$501,$A3)) -> 7 | L3: =IF($A3="","",COUNTIFS(Candidates!$E$2:$E$501,$A3,Candidates!$M$2:$M$501,"Active")) -> 5 | M3: =IF($A3="","",COUNTIFS(Candidates!$E$2:$E$501,$A3,Candidates!$T$2:$T$501,"<>")) -> 4 | N3: =IF($A3="","",COUNTIFS(Candidates!$E$2:$E$501,$A3,Candidates!$K$2:$K$501,"Joined")) -> 2 | O3: =IF($A3="","",MAX($F3-$N3,0)) -> 0 | P3: =IF(OR($A3="",N($F3)=0),"",$N3/$F3) -> 1 | Q3: =IF(OR($A3="",$I3=""),"",TODAY()-$I3) -> 97 | R3: =IF(OR($A3="",$J3=""),"",$J3-TODAY()) -> 16 | S3: =IF($A3="","",IF($O3=0,"Filled",IF(AND($J3<>"",TODAY()>$J3),"Overdue",IF($L3=0,"No Pipeline","Open")))) -> Filled
A4: REQ-103 | B4: Python Backend Developer | C4: Engineering | D4: A. Kumar | E4: Chennai | F4: 2 | G4: Medium | H4: Recruiter 2 | I4: 46223 | J4: 46341 | K4: =IF($A4="","",COUNTIF(Candidates!$E$2:$E$501,$A4)) -> 7 | L4: =IF($A4="","",COUNTIFS(Candidates!$E$2:$E$501,$A4,Candidates!$M$2:$M$501,"Active")) -> 4 | M4: =IF($A4="","",COUNTIFS(Candidates!$E$2:$E$501,$A4,Candidates!$T$2:$T$501,"<>")) -> 4 | N4: =IF($A4="","",COUNTIFS(Candidates!$E$2:$E$501,$A4,Candidates!$K$2:$K$501,"Joined")) -> 1 | O4: =IF($A4="","",MAX($F4-$N4,0)) -> 1 | P4: =IF(OR($A4="",N($F4)=0),"",$N4/$F4) -> 0.5 | Q4: =IF(OR($A4="",$I4=""),"",TODAY()-$I4) -> 87 | R4: =IF(OR($A4="",$J4=""),"",$J4-TODAY()) -> 31 | S4: =IF($A4="","",IF($O4=0,"Filled",IF(AND($J4<>"",TODAY()>$J4),"Overdue",IF($L4=0,"No Pipeline","Open")))) -> Open
A5: REQ-104 | B5: DevOps Engineer | C5: DevOps | D5: R. Nair | E5: Hyderabad | F5: 1 | G5: Medium | H5: Recruiter 3 | I5: 46239 | J5: 46356 | K5: =IF($A5="","",COUNTIF(Candidates!$E$2:$E$501,$A5)) -> 7 | L5: =IF($A5="","",COUNTIFS(Candidates!$E$2:$E$501,$A5,Candidates!$M$2:$M$501,"Active")) -> 4 | M5: =IF($A5="","",COUNTIFS(Candidates!$E$2:$E$501,$A5,Candidates!$T$2:$T$501,"<>")) -> 3 | N5: =IF($A5="","",COUNTIFS(Candidates!$E$2:$E$501,$A5,Candidates!$K$2:$K$501,"Joined")) -> 1 | O5: =IF($A5="","",MAX($F5-$N5,0)) -> 0 | P5: =IF(OR($A5="",N($F5)=0),"",$N5/$F5) -> 1 | Q5: =IF(OR($A5="",$I5=""),"",TODAY()-$I5) -> 71 | R5: =IF(OR($A5="",$J5=""),"",$J5-TODAY()) -> 46 | S5: =IF($A5="","",IF($O5=0,"Filled",IF(AND($J5<>"",TODAY()>$J5),"Overdue",IF($L5=0,"No Pipeline","Open")))) -> Filled
A6: REQ-105 | B6: Data Engineer | C6: Data | D6: P. Das | E6: Pune | F6: 2 | G6: Low | H6: Recruiter 2 | I6: 46254 | J6: 46371 | K6: =IF($A6="","",COUNTIF(Candidates!$E$2:$E$501,$A6)) -> 6 | L6: =IF($A6="","",COUNTIFS(Candidates!$E$2:$E$501,$A6,Candidates!$M$2:$M$501,"Active")) -> 4 | M6: =IF($A6="","",COUNTIFS(Candidates!$E$2:$E$501,$A6,Candidates!$T$2:$T$501,"<>")) -> 4 | N6: =IF($A6="","",COUNTIFS(Candidates!$E$2:$E$501,$A6,Candidates!$K$2:$K$501,"Joined")) -> 2 | O6: =IF($A6="","",MAX($F6-$N6,0)) -> 0 | P6: =IF(OR($A6="",N($F6)=0),"",$N6/$F6) -> 1 | Q6: =IF(OR($A6="",$I6=""),"",TODAY()-$I6) -> 56 | R6: =IF(OR($A6="",$J6=""),"",$J6-TODAY()) -> 61 | S6: =IF($A6="","",IF($O6=0,"Filled",IF(AND($J6<>"",TODAY()>$J6),"Overdue",IF($L6=0,"No Pipeline","Open")))) -> Filled
A7: REQ-106 | B7: Cloud Architect | C7: Cloud | D7: K. Menon | E7: Remote | F7: 1 | G7: High | H7: Recruiter 3 | I7: 46280 | J7: 46387 | K7: =IF($A7="","",COUNTIF(Candidates!$E$2:$E$501,$A7)) -> 6 | L7: =IF($A7="","",COUNTIFS(Candidates!$E$2:$E$501,$A7,Candidates!$M$2:$M$501,"Active")) -> 5 | M7: =IF($A7="","",COUNTIFS(Candidates!$E$2:$E$501,$A7,Candidates!$T$2:$T$501,"<>")) -> 0 | N7: =IF($A7="","",COUNTIFS(Candidates!$E$2:$E$501,$A7,Candidates!$K$2:$K$501,"Joined")) -> 0 | O7: =IF($A7="","",MAX($F7-$N7,0)) -> 1 | P7: =IF(OR($A7="",N($F7)=0),"",$N7/$F7) -> 0 | Q7: =IF(OR($A7="",$I7=""),"",TODAY()-$I7) -> 30 | R7: =IF(OR($A7="",$J7=""),"",$J7-TODAY()) -> 77 | S7: =IF($A7="","",IF($O7=0,"Filled",IF(AND($J7<>"",TODAY()>$J7),"Overdue",IF($L7=0,"No Pipeline","Open")))) -> Open
K8: =IF($A8="","",COUNTIF(Candidates!$E$2:$E$501,$A8)) | L8: =IF($A8="","",COUNTIFS(Candidates!$E$2:$E$501,$A8,Candidates!$M$2:$M$501,"Active")) | M8: =IF($A8="","",COUNTIFS(Candidates!$E$2:$E$501,$A8,Candidates!$T$2:$T$501,"<>")) | N8: =IF($A8="","",COUNTIFS(Candidates!$E$2:$E$501,$A8,Candidates!$K$2:$K$501,"Joined")) | O8: =IF($A8="","",MAX($F8-$N8,0)) | P8: =IF(OR($A8="",N($F8)=0),"",$N8/$F8) | Q8: =IF(OR($A8="",$I8=""),"",TODAY()-$I8) | R8: =IF(OR($A8="",$J8=""),"",$J8-TODAY()) | S8: =IF($A8="","",IF($O8=0,"Filled",IF(AND($J8<>"",TODAY()>$J8),"Overdue",IF($L8=0,"No Pipeline","Open"))))
K9: =IF($A9="","",COUNTIF(Candidates!$E$2:$E$501,$A9)) | L9: =IF($A9="","",COUNTIFS(Candidates!$E$2:$E$501,$A9,Candidates!$M$2:$M$501,"Active")) | M9: =IF($A9="","",COUNTIFS(Candidates!$E$2:$E$501,$A9,Candidates!$T$2:$T$501,"<>")) | N9: =IF($A9="","",COUNTIFS(Candidates!$E$2:$E$501,$A9,Candidates!$K$2:$K$501,"Joined")) | O9: =IF($A9="","",MAX($F9-$N9,0)) | P9: =IF(OR($A9="",N($F9)=0),"",$N9/$F9) | Q9: =IF(OR($A9="",$I9=""),"",TODAY()-$I9) | R9: =IF(OR($A9="",$J9=""),"",$J9-TODAY()) | S9: =IF($A9="","",IF($O9=0,"Filled",IF(AND($J9<>"",TODAY()>$J9),"Overdue",IF($L9=0,"No Pipeline","Open"))))
K10: =IF($A10="","",COUNTIF(Candidates!$E$2:$E$501,$A10)) | L10: =IF($A10="","",COUNTIFS(Candidates!$E$2:$E$501,$A10,Candidates!$M$2:$M$501,"Active")) | M10: =IF($A10="","",COUNTIFS(Candidates!$E$2:$E$501,$A10,Candidates!$T$2:$T$501,"<>")) | N10: =IF($A10="","",COUNTIFS(Candidates!$E$2:$E$501,$A10,Candidates!$K$2:$K$501,"Joined")) | O10: =IF($A10="","",MAX($F10-$N10,0)) | P10: =IF(OR($A10="",N($F10)=0),"",$N10/$F10) | Q10: =IF(OR($A10="",$I10=""),"",TODAY()-$I10) | R10: =IF(OR($A10="",$J10=""),"",$J10-TODAY()) | S10: =IF($A10="","",IF($O10=0,"Filled",IF(AND($J10<>"",TODAY()>$J10),"Overdue",IF($L10=0,"No Pipeline","Open"))))
K11: =IF($A11="","",COUNTIF(Candidates!$E$2:$E$501,$A11)) | L11: =IF($A11="","",COUNTIFS(Candidates!$E$2:$E$501,$A11,Candidates!$M$2:$M$501,"Active")) | M11: =IF($A11="","",COUNTIFS(Candidates!$E$2:$E$501,$A11,Candidates!$T$2:$T$501,"<>")) | N11: =IF($A11="","",COUNTIFS(Candidates!$E$2:$E$501,$A11,Candidates!$K$2:$K$501,"Joined")) | O11: =IF($A11="","",MAX($F11-$N11,0)) | P11: =IF(OR($A11="",N($F11)=0),"",$N11/$F11) | Q11: =IF(OR($A11="",$I11=""),"",TODAY()-$I11) | R11: =IF(OR($A11="",$J11=""),"",$J11-TODAY()) | S11: =IF($A11="","",IF($O11=0,"Filled",IF(AND($J11<>"",TODAY()>$J11),"Overdue",IF($L11=0,"No Pipeline","Open"))))
K12: =IF($A12="","",COUNTIF(Candidates!$E$2:$E$501,$A12)) | L12: =IF($A12="","",COUNTIFS(Candidates!$E$2:$E$501,$A12,Candidates!$M$2:$M$501,"Active")) | M12: =IF($A12="","",COUNTIFS(Candidates!$E$2:$E$501,$A12,Candidates!$T$2:$T$501,"<>")) | N12: =IF($A12="","",COUNTIFS(Candidates!$E$2:$E$501,$A12,Candidates!$K$2:$K$501,"Joined")) | O12: =IF($A12="","",MAX($F12-$N12,0)) | P12: =IF(OR($A12="",N($F12)=0),"",$N12/$F12) | Q12: =IF(OR($A12="",$I12=""),"",TODAY()-$I12) | R12: =IF(OR($A12="",$J12=""),"",$J12-TODAY()) | S12: =IF($A12="","",IF($O12=0,"Filled",IF(AND($J12<>"",TODAY()>$J12),"Overdue",IF($L12=0,"No Pipeline","Open"))))
K13: =IF($A13="","",COUNTIF(Candidates!$E$2:$E$501,$A13)) | L13: =IF($A13="","",COUNTIFS(Candidates!$E$2:$E$501,$A13,Candidates!$M$2:$M$501,"Active")) | M13: =IF($A13="","",COUNTIFS(Candidates!$E$2:$E$501,$A13,Candidates!$T$2:$T$501,"<>")) | N13: =IF($A13="","",COUNTIFS(Candidates!$E$2:$E$501,$A13,Candidates!$K$2:$K$501,"Joined")) | O13: =IF($A13="","",MAX($F13-$N13,0)) | P13: =IF(OR($A13="",N($F13)=0),"",$N13/$F13) | Q13: =IF(OR($A13="",$I13=""),"",TODAY()-$I13) | R13: =IF(OR($A13="",$J13=""),"",$J13-TODAY()) | S13: =IF($A13="","",IF($O13=0,"Filled",IF(AND($J13<>"",TODAY()>$J13),"Overdue",IF($L13=0,"No Pipeline","Open"))))
K14: =IF($A14="","",COUNTIF(Candidates!$E$2:$E$501,$A14)) | L14: =IF($A14="","",COUNTIFS(Candidates!$E$2:$E$501,$A14,Candidates!$M$2:$M$501,"Active")) | M14: =IF($A14="","",COUNTIFS(Candidates!$E$2:$E$501,$A14,Candidates!$T$2:$T$501,"<>")) | N14: =IF($A14="","",COUNTIFS(Candidates!$E$2:$E$501,$A14,Candidates!$K$2:$K$501,"Joined")) | O14: =IF($A14="","",MAX($F14-$N14,0)) | P14: =IF(OR($A14="",N($F14)=0),"",$N14/$F14) | Q14: =IF(OR($A14="",$I14=""),"",TODAY()-$I14) | R14: =IF(OR($A14="",$J14=""),"",$J14-TODAY()) | S14: =IF($A14="","",IF($O14=0,"Filled",IF(AND($J14<>"",TODAY()>$J14),"Overdue",IF($L14=0,"No Pipeline","Open"))))
K15: =IF($A15="","",COUNTIF(Candidates!$E$2:$E$501,$A15)) | L15: =IF($A15="","",COUNTIFS(Candidates!$E$2:$E$501,$A15,Candidates!$M$2:$M$501,"Active")) | M15: =IF($A15="","",COUNTIFS(Candidates!$E$2:$E$501,$A15,Candidates!$T$2:$T$501,"<>")) | N15: =IF($A15="","",COUNTIFS(Candidates!$E$2:$E$501,$A15,Candidates!$K$2:$K$501,"Joined")) | O15: =IF($A15="","",MAX($F15-$N15,0)) | P15: =IF(OR($A15="",N($F15)=0),"",$N15/$F15) | Q15: =IF(OR($A15="",$I15=""),"",TODAY()-$I15) | R15: =IF(OR($A15="",$J15=""),"",$J15-TODAY()) | S15: =IF($A15="","",IF($O15=0,"Filled",IF(AND($J15<>"",TODAY()>$J15),"Overdue",IF($L15=0,"No Pipeline","Open"))))
K16: =IF($A16="","",COUNTIF(Candidates!$E$2:$E$501,$A16)) | L16: =IF($A16="","",COUNTIFS(Candidates!$E$2:$E$501,$A16,Candidates!$M$2:$M$501,"Active")) | M16: =IF($A16="","",COUNTIFS(Candidates!$E$2:$E$501,$A16,Candidates!$T$2:$T$501,"<>")) | N16: =IF($A16="","",COUNTIFS(Candidates!$E$2:$E$501,$A16,Candidates!$K$2:$K$501,"Joined")) | O16: =IF($A16="","",MAX($F16-$N16,0)) | P16: =IF(OR($A16="",N($F16)=0),"",$N16/$F16) | Q16: =IF(OR($A16="",$I16=""),"",TODAY()-$I16) | R16: =IF(OR($A16="",$J16=""),"",$J16-TODAY()) | S16: =IF($A16="","",IF($O16=0,"Filled",IF(AND($J16<>"",TODAY()>$J16),"Overdue",IF($L16=0,"No Pipeline","Open"))))
K17: =IF($A17="","",COUNTIF(Candidates!$E$2:$E$501,$A17)) | L17: =IF($A17="","",COUNTIFS(Candidates!$E$2:$E$501,$A17,Candidates!$M$2:$M$501,"Active")) | M17: =IF($A17="","",COUNTIFS(Candidates!$E$2:$E$501,$A17,Candidates!$T$2:$T$501,"<>")) | N17: =IF($A17="","",COUNTIFS(Candidates!$E$2:$E$501,$A17,Candidates!$K$2:$K$501,"Joined")) | O17: =IF($A17="","",MAX($F17-$N17,0)) | P17: =IF(OR($A17="",N($F17)=0),"",$N17/$F17) | Q17: =IF(OR($A17="",$I17=""),"",TODAY()-$I17) | R17: =IF(OR($A17="",$J17=""),"",$J17-TODAY()) | S17: =IF($A17="","",IF($O17=0,"Filled",IF(AND($J17<>"",TODAY()>$J17),"Overdue",IF($L17=0,"No Pipeline","Open"))))
K18: =IF($A18="","",COUNTIF(Candidates!$E$2:$E$501,$A18)) | L18: =IF($A18="","",COUNTIFS(Candidates!$E$2:$E$501,$A18,Candidates!$M$2:$M$501,"Active")) | M18: =IF($A18="","",COUNTIFS(Candidates!$E$2:$E$501,$A18,Candidates!$T$2:$T$501,"<>")) | N18: =IF($A18="","",COUNTIFS(Candidates!$E$2:$E$501,$A18,Candidates!$K$2:$K$501,"Joined")) | O18: =IF($A18="","",MAX($F18-$N18,0)) | P18: =IF(OR($A18="",N($F18)=0),"",$N18/$F18) | Q18: =IF(OR($A18="",$I18=""),"",TODAY()-$I18) | R18: =IF(OR($A18="",$J18=""),"",$J18-TODAY()) | S18: =IF($A18="","",IF($O18=0,"Filled",IF(AND($J18<>"",TODAY()>$J18),"Overdue",IF($L18=0,"No Pipeline","Open"))))
K19: =IF($A19="","",COUNTIF(Candidates!$E$2:$E$501,$A19)) | L19: =IF($A19="","",COUNTIFS(Candidates!$E$2:$E$501,$A19,Candidates!$M$2:$M$501,"Active")) | M19: =IF($A19="","",COUNTIFS(Candidates!$E$2:$E$501,$A19,Candidates!$T$2:$T$501,"<>")) | N19: =IF($A19="","",COUNTIFS(Candidates!$E$2:$E$501,$A19,Candidates!$K$2:$K$501,"Joined")) | O19: =IF($A19="","",MAX($F19-$N19,0)) | P19: =IF(OR($A19="",N($F19)=0),"",$N19/$F19) | Q19: =IF(OR($A19="",$I19=""),"",TODAY()-$I19) | R19: =IF(OR($A19="",$J19=""),"",$J19-TODAY()) | S19: =IF($A19="","",IF($O19=0,"Filled",IF(AND($J19<>"",TODAY()>$J19),"Overdue",IF($L19=0,"No Pipeline","Open"))))
... K101: =IF($A101="","",COUNTIF(Candidates!$E$2:$E$501,$A101)) | L101: =IF($A101="","",COUNTIFS(Candidates!$E$2:$E$501,$A101,Candidates!$M$2:$M$501,"Active")) | M101: =IF($A101="","",COUNTIFS(Candidates!$E$2:$E$501,$A101,Candidates!$T$2:$T$501,"<>")) | N101: =IF($A101="","",COUNTIFS(Candidates!$E$2:$E$501,$A101,Candidates!$K$2:$K$501,"Joined")) | O101: =IF($A101="","",MAX($F101-$N101,0)) | P101: =IF(OR($A101="",N($F101)=0),"",$N101/$F101) | Q101: =IF(OR($A101="",$I101=""),"",TODAY()-$I101) | R101: =IF(OR($A101="",$J101=""),"",$J101-TODAY()) | S101: =IF($A101="","",IF($O101=0,"Filled",IF(AND($J101<>"",TODAY()>$J101),"Overdue",IF($L101=0,"No Pipeline","Open"))))

Sheet Candidates
A1: Candidate ID | B1: Candidate Name | C1: Email | D1: Phone | E1: Req ID | F1: Role | G1: Hiring Manager | H1: Source | I1: Recruiter | J1: Applied Date | K1: Current Stage | L1: Stage Updated On | M1: Pipeline Status | N1: Dropped At Stage | O1: Exp (yrs) | P1: Current CTC (LPA) | Q1: Expected CTC (LPA) | R1: Notice (days) | S1: Interview Rating (1-5) | T1: Offer Date | U1: Joining Date | V1: Hike % | W1: Days in Pipeline | X1: Days in Stage | Y1: Stage SLA (days) | Z1: SLA Status | AA1: Next Action | AB1: Expected Joining | AC1: Time to Offer (days) | AD1: Time to Hire (days) | AE1: Furthest Stage #
A2: =IF($B2="","","C-"&TEXT(ROW()-1,"0000")) -> C-0001 | B2: Arun Kumar | C2: arun.0@mail.com | D2: 9644854973 | E2: REQ-101 | F2: =IF($E2="","",IFERROR(INDEX(Requisitions!$B$2:$B$101,MATCH($E2,Requisitions!$A$2:$A$101,0)),"Unknown Req")) -> QA Automation Engineer (Python) | G2: =IF($E2="","",IFERROR(INDEX(Requisitions!$D$2:$D$101,MATCH($E2,Requisitions!$A$2:$A$101,0)),"")) -> S. Raman | H2: Naukri | I2: Pravin Christo | J2: 46184 | K2: HR Round | L2: 46305 | M2: =IF($K2="","",IFERROR(INDEX(Lists!$D$4:$D$14,MATCH($K2,Lists!$A$4:$A$14,0)),"Check stage")) -> Active | O2: 1.5 | P2: 12.3 | Q2: 14.4 | R2: 15 | S2: 4 | V2: =IF(OR(N($P2)=0,$Q2=""),"",$Q2/$P2-1) -> 0.17073171 | W2: =IF($J2="","",IF($M2="Active",TODAY(),IF($U2<>"",$U2,IF($L2<>"",$L2,TODAY())))-$J2) -> 126 | X2: =IF(OR($L2="",$M2<>"Active"),"",TODAY()-$L2) -> 5 | Y2: =IF($M2<>"Active","",INDEX(Lists!$C$4:$C$14,MATCH($K2,Lists!$A$4:$A$14,0))) -> 3 | Z2: =IF($B2="","",IF($M2<>"Active","Closed",IF($X2="","",IF($X2>$Y2,"BREACH","On Track")))) -> BREACH | AA2: =IF($K2="","",IFERROR(INDEX(Lists!$E$4:$E$14,MATCH($K2,Lists!$A$4:$A$14,0)),"")) -> HR discussion & salary alignment | AB2: =IF($U2<>"",$U2,IF(OR($T2="",$M2<>"Active"),"",$T2+N($R2))) | AC2: =IF(OR($T2="",$J2=""),"",$T2-$J2) | AD2: =IF(AND($K2="Joined",$U2<>"",$J2<>""),$U2-$J2,"") | AE2: =IF($K2="","",IF(OR($K2="Rejected",$K2="Withdrawn"),IFERROR(INDEX(Lists!$B$4:$B$14,MATCH($N2,Lists!$A$4:$A$14,0)),1),IFERROR(INDEX(Lists!$B$4:$B$14,MATCH($K2,Lists!$A$4:$A$14,0)),0))) -> 5
A3: =IF($B3="","","C-"&TEXT(ROW()-1,"0000")) -> C-0002 | B3: Divya Das | C3: divya.1@mail.com | D3: 9166423868 | E3: REQ-102 | F3: =IF($E3="","",IFERROR(INDEX(Requisitions!$B$2:$B$101,MATCH($E3,Requisitions!$A$2:$A$101,0)),"Unknown Req")) -> Senior SDET | G3: =IF($E3="","",IFERROR(INDEX(Requisitions!$D$2:$D$101,MATCH($E3,Requisitions!$A$2:$A$101,0)),"")) -> M. Iyer | H3: Indeed | I3: Pravin Christo | J3: 46240 | K3: Offer Accepted | L3: 46260 | M3: =IF($K3="","",IFERROR(INDEX(Lists!$D$4:$D$14,MATCH($K3,Lists!$A$4:$A$14,0)),"Check stage")) -> Active | O3: 8.6 | P3: 5.5 | Q3: 6.5 | R3: 90 | S3: 3 | T3: 46259 | V3: =IF(OR(N($P3)=0,$Q3=""),"",$Q3/$P3-1) -> 0.18181818 | W3: =IF($J3="","",IF($M3="Active",TODAY(),IF($U3<>"",$U3,IF($L3<>"",$L3,TODAY())))-$J3) -> 70 | X3: =IF(OR($L3="",$M3<>"Active"),"",TODAY()-$L3) -> 50 | Y3: =IF($M3<>"Active","",INDEX(Lists!$C$4:$C$14,MATCH($K3,Lists!$A$4:$A$14,0))) -> 30 | Z3: =IF($B3="","",IF($M3<>"Active","Closed",IF($X3="","",IF($X3>$Y3,"BREACH","On Track")))) -> BREACH | AA3: =IF($K3="","",IFERROR(INDEX(Lists!$E$4:$E$14,MATCH($K3,Lists!$A$4:$A$14,0)),"")) -> Pre-joining engagement & docs | AB3: =IF($U3<>"",$U3,IF(OR($T3="",$M3<>"Active"),"",$T3+N($R3))) -> 46349 | AC3: =IF(OR($T3="",$J3=""),"",$T3-$J3) -> 19 | AD3: =IF(AND($K3="Joined",$U3<>"",$J3<>""),$U3-$J3,"") | AE3: =IF($K3="","",IF(OR($K3="Rejected",$K3="Withdrawn"),IFERROR(INDEX(Lists!$B$4:$B$14,MATCH($N3,Lists!$A$4:$A$14,0)),1),IFERROR(INDEX(Lists!$B$4:$B$14,MATCH($K3,Lists!$A$4:$A$14,0)),0))) -> 7
A4: =IF($B4="","","C-"&TEXT(ROW()-1,"0000")) -> C-0003 | B4: Ravi S | C4: ravi.2@mail.com | D4: 9680557051 | E4: REQ-103 | F4: =IF($E4="","",IFERROR(INDEX(Requisitions!$B$2:$B$101,MATCH($E4,Requisitions!$A$2:$A$101,0)),"Unknown Req")) -> Python Backend Developer | G4: =IF($E4="","",IFERROR(INDEX(Requisitions!$D$2:$D$101,MATCH($E4,Requisitions!$A$2:$A$101,0)),"")) -> A. Kumar | H4: LinkedIn | I4: Recruiter 2 | J4: 46238 | K4: Sourced | L4: 46304 | M4: =IF($K4="","",IFERROR(INDEX(Lists!$D$4:$D$14,MATCH($K4,Lists!$A$4:$A$14,0)),"Check stage")) -> Active | O4: 8.4 | P4: 5 | Q4: 7.5 | R4: 60 | V4: =IF(OR(N($P4)=0,$Q4=""),"",$Q4/$P4-1) -> 0.5 | W4: =IF($J4="","",IF($M4="Active",TODAY(),IF($U4<>"",$U4,IF($L4<>"",$L4,TODAY())))-$J4) -> 72 | X4: =IF(OR($L4="",$M4<>"Active"),"",TODAY()-$L4) -> 6 | Y4: =IF($M4<>"Active","",INDEX(Lists!$C$4:$C$14,MATCH($K4,Lists!$A$4:$A$14,0))) -> 3 | Z4: =IF($B4="","",IF($M4<>"Active","Closed",IF($X4="","",IF($X4>$Y4,"BREACH","On Track")))) -> BREACH | AA4: =IF($K4="","",IFERROR(INDEX(Lists!$E$4:$E$14,MATCH($K4,Lists!$A$4:$A$14,0)),"")) -> Reach out & share JD | AB4: =IF($U4<>"",$U4,IF(OR($T4="",$M4<>"Active"),"",$T4+N($R4))) | AC4: =IF(OR($T4="",$J4=""),"",$T4-$J4) | AD4: =IF(AND($K4="Joined",$U4<>"",$J4<>""),$U4-$J4,"") | AE4: =IF($K4="","",IF(OR($K4="Rejected",$K4="Withdrawn"),IFERROR(INDEX(Lists!$B$4:$B$14,MATCH($N4,Lists!$A$4:$A$14,0)),1),IFERROR(INDEX(Lists!$B$4:$B$14,MATCH($K4,Lists!$A$4:$A$14,0)),0))) -> 1
A5: =IF($B5="","","C-"&TEXT(ROW()-1,"0000")) -> C-0004 | B5: Sneha R | C5: sneha.3@mail.com | D5: 9705985840 | E5: REQ-104 | F5: =IF($E5="","",IFERROR(INDEX(Requisitions!$B$2:$B$101,MATCH($E5,Requisitions!$A$2:$A$101,0)),"Unknown Req")) -> DevOps Engineer | G5: =IF($E5="","",IFERROR(INDEX(Requisitions!$D$2:$D$101,MATCH($E5,Requisitions!$A$2:$A$101,0)),"")) -> R. Nair | H5: LinkedIn | I5: Recruiter 3 | J5: 46251 | K5: Rejected | L5: 46270 | M5: =IF($K5="","",IFERROR(INDEX(Lists!$D$4:$D$14,MATCH($K5,Lists!$A$4:$A$14,0)),"Check stage")) -> Lost | N5: Tech Round 1 | O5: 9 | P5: 6.2 | Q5: 8.5 | R5: 30 | S5: 5 | V5: =IF(OR(N($P5)=0,$Q5=""),"",$Q5/$P5-1) -> 0.37096774 | W5: =IF($J5="","",IF($M5="Active",TODAY(),IF($U5<>"",$U5,IF($L5<>"",$L5,TODAY())))-$J5) -> 19 | X5: =IF(OR($L5="",$M5<>"Active"),"",TODAY()-$L5) | Y5: =IF($M5<>"Active","",INDEX(Lists!$C$4:$C$14,MATCH($K5,Lists!$A$4:$A$14,0))) | Z5: =IF($B5="","",IF($M5<>"Active","Closed",IF($X5="","",IF($X5>$Y5,"BREACH","On Track")))) -> Closed | AA5: =IF($K5="","",IFERROR(INDEX(Lists!$E$4:$E$14,MATCH($K5,Lists!$A$4:$A$14,0)),"")) -> Send regret email | AB5: =IF($U5<>"",$U5,IF(OR($T5="",$M5<>"Active"),"",$T5+N($R5))) | AC5: =IF(OR($T5="",$J5=""),"",$T5-$J5) | AD5: =IF(AND($K5="Joined",$U5<>"",$J5<>""),$U5-$J5,"") | AE5: =IF($K5="","",IF(OR($K5="Rejected",$K5="Withdrawn"),IFERROR(INDEX(Lists!$B$4:$B$14,MATCH($N5,Lists!$A$4:$A$14,0)),1),IFERROR(INDEX(Lists!$B$4:$B$14,MATCH($K5,Lists!$A$4:$A$14,0)),0))) -> 3
A6: =IF($B6="","","C-"&TEXT(ROW()-1,"0000")) -> C-0005 | B6: Vikram S | C6: vikram.4@mail.com | D6: 9850539557 | E6: REQ-105 | F6: =IF($E6="","",IFERROR(INDEX(Requisitions!$B$2:$B$101,MATCH($E6,Requisitions!$A$2:$A$101,0)),"Unknown Req")) -> Data Engineer | G6: =IF($E6="","",IFERROR(INDEX(Requisitions!$D$2:$D$101,MATCH($E6,Requisitions!$A$2:$A$101,0)),"")) -> P. Das | H6: Naukri | I6: Recruiter 2 | J6: 46268 | K6: Joined | L6: 46309 | M6: =IF($K6="","",IFERROR(INDEX(Lists!$D$4:$D$14,MATCH($K6,Lists!$A$4:$A$14,0)),"Check stage")) -> Hired | O6: 2.1 | P6: 20.3 | Q6: 27.1 | R6: 90 | S6: 3 | T6: 46297 | U6: 46309 | V6: =IF(OR(N($P6)=0,$Q6=""),"",$Q6/$P6-1) -> 0.33497537 | W6: =IF($J6="","",IF($M6="Active",TODAY(),IF($U6<>"",$U6,IF($L6<>"",$L6,TODAY())))-$J6) -> 41 | X6: =IF(OR($L6="",$M6<>"Active"),"",TODAY()-$L6) | Y6: =IF($M6<>"Active","",INDEX(Lists!$C$4:$C$14,MATCH($K6,Lists!$A$4:$A$14,0))) | Z6: =IF($B6="","",IF($M6<>"Active","Closed",IF($X6="","",IF($X6>$Y6,"BREACH","On Track")))) -> Closed | AA6: =IF($K6="","",IFERROR(INDEX(Lists!$E$4:$E$14,MATCH($K6,Lists!$A$4:$A$14,0)),"")) -> Onboarding complete | AB6: =IF($U6<>"",$U6,IF(OR($T6="",$M6<>"Active"),"",$T6+N($R6))) -> 46309 | AC6: =IF(OR($T6="",$J6=""),"",$T6-$J6) -> 29 | AD6: =IF(AND($K6="Joined",$U6<>"",$J6<>""),$U6-$J6,"") -> 41 | AE6: =IF($K6="","",IF(OR($K6="Rejected",$K6="Withdrawn"),IFERROR(INDEX(Lists!$B$4:$B$14,MATCH($N6,Lists!$A$4:$A$14,0)),1),IFERROR(INDEX(Lists!$B$4:$B$14,MATCH($K6,Lists!$A$4:$A$14,0)),0))) -> 8
A7: =IF($B7="","","C-"&TEXT(ROW()-1,"0000")) -> C-0006 | B7: Priya R | C7: priya.5@mail.com | D7: 9226772164 | E7: REQ-106 | F7: =IF($E7="","",IFERROR(INDEX(Requisitions!$B$2:$B$101,MATCH($E7,Requisitions!$A$2:$A$101,0)),"Unknown Req")) -> Cloud Architect | G7: =IF($E7="","",IFERROR(INDEX(Requisitions!$D$2:$D$101,MATCH($E7,Requisitions!$A$2:$A$101,0)),"")) -> K. Menon | H7: Indeed | I7: Recruiter 3 | J7: 46305 | K7: HR Round | L7: 46306 | M7: =IF($K7="","",IFERROR(INDEX(Lists!$D$4:$D$14,MATCH($K7,Lists!$A$4:$A$14,0)),"Check stage")) -> Active | O7: 6.4 | P7: 14.4 | Q7: 18.5 | R7: 90 | S7: 4 | V7: =IF(OR(N($P7)=0,$Q7=""),"",$Q7/$P7-1) -> 0.28472222 | W7: =IF($J7="","",IF($M7="Active",TODAY(),IF($U7<>"",$U7,IF($L7<>"",$L7,TODAY())))-$J7) -> 5 | X7: =IF(OR($L7="",$M7<>"Active"),"",TODAY()-$L7) -> 4 | Y7: =IF($M7<>"Active","",INDEX(Lists!$C$4:$C$14,MATCH($K7,Lists!$A$4:$A$14,0))) -> 3 | Z7: =IF($B7="","",IF($M7<>"Active","Closed",IF($X7="","",IF($X7>$Y7,"BREACH","On Track")))) -> BREACH | AA7: =IF($K7="","",IFERROR(INDEX(Lists!$E$4:$E$14,MATCH($K7,Lists!$A$4:$A$14,0)),"")) -> HR discussion & salary alignment | AB7: =IF($U7<>"",$U7,IF(OR($T7="",$M7<>"Active"),"",$T7+N($R7))) | AC7: =IF(OR($T7="",$J7=""),"",$T7-$J7) | AD7: =IF(AND($K7="Joined",$U7<>"",$J7<>""),$U7-$J7,"") | AE7: =IF($K7="","",IF(OR($K7="Rejected",$K7="Withdrawn"),IFERROR(INDEX(Lists!$B$4:$B$14,MATCH($N7,Lists!$A$4:$A$14,0)),1),IFERROR(INDEX(Lists!$B$4:$B$14,MATCH($K7,Lists!$A$4:$A$14,0)),0))) -> 5
A8: =IF($B8="","","C-"&TEXT(ROW()-1,"0000")) -> C-0007 | B8: Karthik Nair | C8: karthik.6@mail.com | D8: 9738199795 | E8: REQ-101 | F8: =IF($E8="","",IFERROR(INDEX(Requisitions!$B$2:$B$101,MATCH($E8,Requisitions!$A$2:$A$101,0)),"Unknown Req")) -> QA Automation Engineer (Python) | G8: =IF($E8="","",IFERROR(INDEX(Requisitions!$D$2:$D$101,MATCH($E8,Requisitions!$A$2:$A$101,0)),"")) -> S. Raman | H8: Career Page | I8: Pravin Christo | J8: 46184 | K8: HR Round | L8: 46305 | M8: =IF($K8="","",IFERROR(INDEX(Lists!$D$4:$D$14,MATCH($K8,Lists!$A$4:$A$14,0)),"Check stage")) -> Active | O8: 8.5 | P8: 23.6 | Q8: 31.1 | R8: 15 | S8: 3 | V8: =IF(OR(N($P8)=0,$Q8=""),"",$Q8/$P8-1) -> 0.31779661 | W8: =IF($J8="","",IF($M8="Active",TODAY(),IF($U8<>"",$U8,IF($L8<>"",$L8,TODAY())))-$J8) -> 126 | X8: =IF(OR($L8="",$M8<>"Active"),"",TODAY()-$L8) -> 5 | Y8: =IF($M8<>"Active","",INDEX(Lists!$C$4:$C$14,MATCH($K8,Lists!$A$4:$A$14,0))) -> 3 | Z8: =IF($B8="","",IF($M8<>"Active","Closed",IF($X8="","",IF($X8>$Y8,"BREACH","On Track")))) -> BREACH | AA8: =IF($K8="","",IFERROR(INDEX(Lists!$E$4:$E$14,MATCH($K8,Lists!$A$4:$A$14,0)),"")) -> HR discussion & salary alignment | AB8: =IF($U8<>"",$U8,IF(OR($T8="",$M8<>"Active"),"",$T8+N($R8))) | AC8: =IF(OR($T8="",$J8=""),"",$T8-$J8) | AD8: =IF(AND($K8="Joined",$U8<>"",$J8<>""),$U8-$J8,"") | AE8: =IF($K8="","",IF(OR($K8="Rejected",$K8="Withdrawn"),IFERROR(INDEX(Lists!$B$4:$B$14,MATCH($N8,Lists!$A$4:$A$14,0)),1),IFERROR(INDEX(Lists!$B$4:$B$14,MATCH($K8,Lists!$A$4:$A$14,0)),0))) -> 5
A9: =IF($B9="","","C-"&TEXT(ROW()-1,"0000")) -> C-0008 | B9: Meera Das | C9: meera.7@mail.com | D9: 9831472844 | E9: REQ-102 | F9: =IF($E9="","",IFERROR(INDEX(Requisitions!$B$2:$B$101,MATCH($E9,Requisitions!$A$2:$A$101,0)),"Unknown Req")) -> Senior SDET | G9: =IF($E9="","",IFERROR(INDEX(Requisitions!$D$2:$D$101,MATCH($E9,Requisitions!$A$2:$A$101,0)),"")) -> M. Iyer | H9: Career Page | I9: Pravin Christo | J9: 46216 | K9: Joined | L9: 46250 | M9: =IF($K9="","",IFERROR(INDEX(Lists!$D$4:$D$14,MATCH($K9,Lists!$A$4:$A$14,0)),"Check stage")) -> Hired | O9: 4.7 | P9: 23.8 | Q9: 31.9 | R9: 15 | S9: 5 | T9: 46235 | U9: 46250 | V9: =IF(OR(N($P9)=0,$Q9=""),"",$Q9/$P9-1) -> 0.34033613 | W9: =IF($J9="","",IF($M9="Active",TODAY(),IF($U9<>"",$U9,IF($L9<>"",$L9,TODAY())))-$J9) -> 34 | X9: =IF(OR($L9="",$M9<>"Active"),"",TODAY()-$L9) | Y9: =IF($M9<>"Active","",INDEX(Lists!$C$4:$C$14,MATCH($K9,Lists!$A$4:$A$14,0))) | Z9: =IF($B9="","",IF($M9<>"Active","Closed",IF($X9="","",IF($X9>$Y9,"BREACH","On Track")))) -> Closed | AA9: =IF($K9="","",IFERROR(INDEX(Lists!$E$4:$E$14,MATCH($K9,Lists!$A$4:$A$14,0)),"")) -> Onboarding complete | AB9: =IF($U9<>"",$U9,IF(OR($T9="",$M9<>"Active"),"",$T9+N($R9))) -> 46250 | AC9: =IF(OR($T9="",$J9=""),"",$T9-$J9) -> 19 | AD9: =IF(AND($K9="Joined",$U9<>"",$J9<>""),$U9-$J9,"") -> 34 | AE9: =IF($K9="","",IF(OR($K9="Rejected",$K9="Withdrawn"),IFERROR(INDEX(Lists!$B$4:$B$14,MATCH($N9,Lists!$A$4:$A$14,0)),1),IFERROR(INDEX(Lists!$B$4:$B$14,MATCH($K9,Lists!$A$4:$A$14,0)),0))) -> 8
A10: =IF($B10="","","C-"&TEXT(ROW()-1,"0000")) -> C-0009 | B10: Rahul Menon | C10: rahul.8@mail.com | D10: 9924883888 | E10: REQ-103 | F10: =IF($E10="","",IFERROR(INDEX(Requisitions!$B$2:$B$101,MATCH($E10,Requisitions!$A$2:$A$101,0)),"Unknown Req")) -> Python Backend Developer | G10: =IF($E10="","",IFERROR(INDEX(Requisitions!$D$2:$D$101,MATCH($E10,Requisitions!$A$2:$A$101,0)),"")) -> A. Kumar | H10: Referral | I10: Recruiter 2 | J10: 46246 | K10: Offered | L10: 46267 | M10: =IF($K10="","",IFERROR(INDEX(Lists!$D$4:$D$14,MATCH($K10,Lists!$A$4:$A$14,0)),"Check stage")) -> Active | O10: 2.7 | P10: 4.5 | Q10: 6 | R10: 30 | S10: 2 | T10: 46267 | V10: =IF(OR(N($P10)=0,$Q10=""),"",$Q10/$P10-1) -> 0.33333333 | W10: =IF($J10="","",IF($M10="Active",TODAY(),IF($U10<>"",$U10,IF($L10<>"",$L10,TODAY())))-$J10) -> 64 | X10: =IF(OR($L10="",$M10<>"Active"),"",TODAY()-$L10) -> 43 | Y10: =IF($M10<>"Active","",INDEX(Lists!$C$4:$C$14,MATCH($K10,Lists!$A$4:$A$14,0))) -> 5 | Z10: =IF($B10="","",IF($M10<>"Active","Closed",IF($X10="","",IF($X10>$Y10,"BREACH","On Track")))) -> BREACH | AA10: =IF($K10="","",IFERROR(INDEX(Lists!$E$4:$E$14,MATCH($K10,Lists!$A$4:$A$14,0)),"")) -> Follow up on offer acceptance | AB10: =IF($U10<>"",$U10,IF(OR($T10="",$M10<>"Active"),"",$T10+N($R10))) -> 46297 | AC10: =IF(OR($T10="",$J10=""),"",$T10-$J10) -> 21 | AD10: =IF(AND($K10="Joined",$U10<>"",$J10<>""),$U10-$J10,"") | AE10: =IF($K10="","",IF(OR($K10="Rejected",$K10="Withdrawn"),IFERROR(INDEX(Lists!$B$4:$B$14,MATCH($N10,Lists!$A$4:$A$14,0)),1),IFERROR(INDEX(Lists!$B$4:$B$14,MATCH($K10,Lists!$A$4:$A$14,0)),0))) -> 6
A11: =IF($B11="","","C-"&TEXT(ROW()-1,"0000")) -> C-0010 | B11: Anjali Iyer | C11: anjali.9@mail.com | D11: 9689956612 | E11: REQ-104 | F11: =IF($E11="","",IFERROR(INDEX(Requisitions!$B$2:$B$101,MATCH($E11,Requisitions!$A$2:$A$101,0)),"Unknown Req")) -> DevOps Engineer | G11: =IF($E11="","",IFERROR(INDEX(Requisitions!$D$2:$D$101,MATCH($E11,Requisitions!$A$2:$A$101,0)),"")) -> R. Nair | H11: Referral | I11: Recruiter 3 | J11: 46265 | K11: Tech Round 2 | L11: 46308 | M11: =IF($K11="","",IFERROR(INDEX(Lists!$D$4:$D$14,MATCH($K11,Lists!$A$4:$A$14,0)),"Check stage")) -> Active | O11: 12.5 | P11: 12.2 | Q11: 18.3 | R11: 15 | S11: 4 | V11: =IF(OR(N($P11)=0,$Q11=""),"",$Q11/$P11-1) -> 0.5 | W11: =IF($J11="","",IF($M11="Active",TODAY(),IF($U11<>"",$U11,IF($L11<>"",$L11,TODAY())))-$J11) -> 45 | X11: =IF(OR($L11="",$M11<>"Active"),"",TODAY()-$L11) -> 2 | Y11: =IF($M11<>"Active","",INDEX(Lists!$C$4:$C$14,MATCH($K11,Lists!$A$4:$A$14,0))) -> 5 | Z11: =IF($B11="","",IF($M11<>"Active","Closed",IF($X11="","",IF($X11>$Y11,"BREACH","On Track")))) -> On Track | AA11: =IF($K11="","",IFERROR(INDEX(Lists!$E$4:$E$14,MATCH($K11,Lists!$A$4:$A$14,0)),"")) -> Schedule / collect Tech R2 feedback | AB11: =IF($U11<>"",$U11,IF(OR($T11="",$M11<>"Active"),"",$T11+N($R11))) | AC11: =IF(OR($T11="",$J11=""),"",$T11-$J11) | AD11: =IF(AND($K11="Joined",$U11<>"",$J11<>""),$U11-$J11,"") | AE11: =IF($K11="","",IF(OR($K11="Rejected",$K11="Withdrawn"),IFERROR(INDEX(Lists!$B$4:$B$14,MATCH($N11,Lists!$A$4:$A$14,0)),1),IFERROR(INDEX(Lists!$B$4:$B$14,MATCH($K11,Lists!$A$4:$A$14,0)),0))) -> 4
A12: =IF($B12="","","C-"&TEXT(ROW()-1,"0000")) -> C-0011 | B12: Suresh S | C12: suresh.10@mail.com | D12: 9262455407 | E12: REQ-105 | F12: =IF($E12="","",IFERROR(INDEX(Requisitions!$B$2:$B$101,MATCH($E12,Requisitions!$A$2:$A$101,0)),"Unknown Req")) -> Data Engineer | G12: =IF($E12="","",IFERROR(INDEX(Requisitions!$D$2:$D$101,MATCH($E12,Requisitions!$A$2:$A$101,0)),"")) -> P. Das | H12: Naukri | I12: Recruiter 2 | J12: 46290 | K12: Offer Accepted | L12: 46304 | M12: =IF($K12="","",IFERROR(INDEX(Lists!$D$4:$D$14,MATCH($K12,Lists!$A$4:$A$14,0)),"Check stage")) -> Active | O12: 9.6 | P12: 9.8 | Q12: 12.9 | R12: 60 | S12: 2 | T12: 46302 | V12: =IF(OR(N($P12)=0,$Q12=""),"",$Q12/$P12-1) -> 0.31632653 | W12: =IF($J12="","",IF($M12="Active",TODAY(),IF($U12<>"",$U12,IF($L12<>"",$L12,TODAY())))-$J12) -> 20 | X12: =IF(OR($L12="",$M12<>"Active"),"",TODAY()-$L12) -> 6 | Y12: =IF($M12<>"Active","",INDEX(Lists!$C$4:$C$14,MATCH($K12,Lists!$A$4:$A$14,0))) -> 30 | Z12: =IF($B12="","",IF($M12<>"Active","Closed",IF($X12="","",IF($X12>$Y12,"BREACH","On Track")))) -> On Track | AA12: =IF($K12="","",IFERROR(INDEX(Lists!$E$4:$E$14,MATCH($K12,Lists!$A$4:$A$14,0)),"")) -> Pre-joining engagement & docs | AB12: =IF($U12<>"",$U12,IF(OR($T12="",$M12<>"Active"),"",$T12+N($R12))) -> 46362 | AC12: =IF(OR($T12="",$J12=""),"",$T12-$J12) -> 12 | AD12: =IF(AND($K12="Joined",$U12<>"",$J12<>""),$U12-$J12,"") | AE12: =IF($K12="","",IF(OR($K12="Rejected",$K12="Withdrawn"),IFERROR(INDEX(Lists!$B$4:$B$14,MATCH($N12,Lists!$A$4:$A$14,0)),1),IFERROR(INDEX(Lists!$B$4:$B$14,MATCH($K12,Lists!$A$4:$A$14,0)),0))) -> 7
A13: =IF($B13="","","C-"&TEXT(ROW()-1,"0000")) -> C-0012 | B13: Kavya S | C13: kavya.11@mail.com | D13: 9549840379 | E13: REQ-106 | F13: =IF($E13="","",IFERROR(INDEX(Requisitions!$B$2:$B$101,MATCH($E13,Requisitions!$A$2:$A$101,0)),"Unknown Req")) -> Cloud Architect | G13: =IF($E13="","",IFERROR(INDEX(Requisitions!$D$2:$D$101,MATCH($E13,Requisitions!$A$2:$A$101,0)),"")) -> K. Menon | H13: Indeed | I13: Recruiter 3 | J13: 46305 | K13: Sourced | L13: 46310 | M13: =IF($K13="","",IFERROR(INDEX(Lists!$D$4:$D$14,MATCH($K13,Lists!$A$4:$A$14,0)),"Check stage")) -> Active | O13: 5.8 | P13: 21.5 | Q13: 26.3 | R13: 60 | V13: =IF(OR(N($P13)=0,$Q13=""),"",$Q13/$P13-1) -> 0.22325581 | W13: =IF($J13="","",IF($M13="Active",TODAY(),IF($U13<>"",$U13,IF($L13<>"",$L13,TODAY())))-$J13) -> 5 | X13: =IF(OR($L13="",$M13<>"Active"),"",TODAY()-$L13) -> 0 | Y13: =IF($M13<>"Active","",INDEX(Lists!$C$4:$C$14,MATCH($K13,Lists!$A$4:$A$14,0))) -> 3 | Z13: =IF($B13="","",IF($M13<>"Active","Closed",IF($X13="","",IF($X13>$Y13,"BREACH","On Track")))) -> On Track | AA13: =IF($K13="","",IFERROR(INDEX(Lists!$E$4:$E$14,MATCH($K13,Lists!$A$4:$A$14,0)),"")) -> Reach out & share JD | AB13: =IF($U13<>"",$U13,IF(OR($T13="",$M13<>"Active"),"",$T13+N($R13))) | AC13: =IF(OR($T13="",$J13=""),"",$T13-$J13) | AD13: =IF(AND($K13="Joined",$U13<>"",$J13<>""),$U13-$J13,"") | AE13: =IF($K13="","",IF(OR($K13="Rejected",$K13="Withdrawn"),IFERROR(INDEX(Lists!$B$4:$B$14,MATCH($N13,Lists!$A$4:$A$14,0)),1),IFERROR(INDEX(Lists!$B$4:$B$14,MATCH($K13,Lists!$A$4:$A$14,0)),0))) -> 1
A14: =IF($B14="","","C-"&TEXT(ROW()-1,"0000")) -> C-0013 | B14: Manoj Iyer | C14: manoj.12@mail.com | D14: 9211172107 | E14: REQ-101 | F14: =IF($E14="","",IFERROR(INDEX(Requisitions!$B$2:$B$101,MATCH($E14,Requisitions!$A$2:$A$101,0)),"Unknown Req")) -> QA Automation Engineer (Python) | G14: =IF($E14="","",IFERROR(INDEX(Requisitions!$D$2:$D$101,MATCH($E14,Requisitions!$A$2:$A$101,0)),"")) -> S. Raman | H14: Career Page | I14: Pravin Christo | J14: 46195 | K14: Rejected | L14: 46209 | M14: =IF($K14="","",IFERROR(INDEX(Lists!$D$4:$D$14,MATCH($K14,Lists!$A$4:$A$14,0)),"Check stage")) -> Lost | N14: Tech Round 2 | O14: 9.2 | P14: 24 | Q14: 34.2 | R14: 15 | S14: 4 | V14: =IF(OR(N($P14)=0,$Q14=""),"",$Q14/$P14-1) -> 0.425 | W14: =IF($J14="","",IF($M14="Active",TODAY(),IF($U14<>"",$U14,IF($L14<>"",$L14,TODAY())))-$J14) -> 14 | X14: =IF(OR($L14="",$M14<>"Active"),"",TODAY()-$L14) | Y14: =IF($M14<>"Active","",INDEX(Lists!$C$4:$C$14,MATCH($K14,Lists!$A$4:$A$14,0))) | Z14: =IF($B14="","",IF($M14<>"Active","Closed",IF($X14="","",IF($X14>$Y14,"BREACH","On Track")))) -> Closed | AA14: =IF($K14="","",IFERROR(INDEX(Lists!$E$4:$E$14,MATCH($K14,Lists!$A$4:$A$14,0)),"")) -> Send regret email | AB14: =IF($U14<>"",$U14,IF(OR($T14="",$M14<>"Active"),"",$T14+N($R14))) | AC14: =IF(OR($T14="",$J14=""),"",$T14-$J14) | AD14: =IF(AND($K14="Joined",$U14<>"",$J14<>""),$U14-$J14,"") | AE14: =IF($K14="","",IF(OR($K14="Rejected",$K14="Withdrawn"),IFERROR(INDEX(Lists!$B$4:$B$14,MATCH($N14,Lists!$A$4:$A$14,0)),1),IFERROR(INDEX(Lists!$B$4:$B$14,MATCH($K14,Lists!$A$4:$A$14,0)),0))) -> 4
A15: =IF($B15="","","C-"&TEXT(ROW()-1,"0000")) -> C-0014 | B15: Deepa Nair | C15: deepa.13@mail.com | D15: 9745025986 | E15: REQ-102 | F15: =IF($E15="","",IFERROR(INDEX(Requisitions!$B$2:$B$101,MATCH($E15,Requisitions!$A$2:$A$101,0)),"Unknown Req")) -> Senior SDET | G15: =IF($E15="","",IFERROR(INDEX(Requisitions!$D$2:$D$101,MATCH($E15,Requisitions!$A$2:$A$101,0)),"")) -> M. Iyer | H15: LinkedIn | I15: Pravin Christo | J15: 46226 | K15: Sourced | L15: 46309 | M15: =IF($K15="","",IFERROR(INDEX(Lists!$D$4:$D$14,MATCH($K15,Lists!$A$4:$A$14,0)),"Check stage")) -> Active | O15: 2.3 | P15: 5.4 | Q15: 6.7 | R15: 30 | V15: =IF(OR(N($P15)=0,$Q15=""),"",$Q15/$P15-1) -> 0.24074074 | W15: =IF($J15="","",IF($M15="Active",TODAY(),IF($U15<>"",$U15,IF($L15<>"",$L15,TODAY())))-$J15) -> 84 | X15: =IF(OR($L15="",$M15<>"Active"),"",TODAY()-$L15) -> 1 | Y15: =IF($M15<>"Active","",INDEX(Lists!$C$4:$C$14,MATCH($K15,Lists!$A$4:$A$14,0))) -> 3 | Z15: =IF($B15="","",IF($M15<>"Active","Closed",IF($X15="","",IF($X15>$Y15,"BREACH","On Track")))) -> On Track | AA15: =IF($K15="","",IFERROR(INDEX(Lists!$E$4:$E$14,MATCH($K15,Lists!$A$4:$A$14,0)),"")) -> Reach out & share JD | AB15: =IF($U15<>"",$U15,IF(OR($T15="",$M15<>"Active"),"",$T15+N($R15))) | AC15: =IF(OR($T15="",$J15=""),"",$T15-$J15) | AD15: =IF(AND($K15="Joined",$U15<>"",$J15<>""),$U15-$J15,"") | AE15: =IF($K15="","",IF(OR($K15="Rejected",$K15="Withdrawn"),IFERROR(INDEX(Lists!$B$4:$B$14,MATCH($N15,Lists!$A$4:$A$14,0)),1),IFERROR(INDEX(Lists!$B$4:$B$14,MATCH($K15,Lists!$A$4:$A$14,0)),0))) -> 1
A16: =IF($B16="","","C-"&TEXT(ROW()-1,"0000")) -> C-0015 | B16: Ajay Reddy | C16: ajay.14@mail.com | D16: 9473006684 | E16: REQ-103 | F16: =IF($E16="","",IFERROR(INDEX(Requisitions!$B$2:$B$101,MATCH($E16,Requisitions!$A$2:$A$101,0)),"Unknown Req")) -> Python Backend Developer | G16: =IF($E16="","",IFERROR(INDEX(Requisitions!$D$2:$D$101,MATCH($E16,Requisitions!$A$2:$A$101,0)),"")) -> A. Kumar | H16: Indeed | I16: Recruiter 2 | J16: 46233 | K16: Rejected | L16: 46247 | M16: =IF($K16="","",IFERROR(INDEX(Lists!$D$4:$D$14,MATCH($K16,Lists!$A$4:$A$14,0)),"Check stage")) -> Lost | N16: Sourced | O16: 5.7 | P16: 15.3 | Q16: 23.4 | R16: 15 | S16: 3 | V16: =IF(OR(N($P16)=0,$Q16=""),"",$Q16/$P16-1) -> 0.52941176 | W16: =IF($J16="","",IF($M16="Active",TODAY(),IF($U16<>"",$U16,IF($L16<>"",$L16,TODAY())))-$J16) -> 14 | X16: =IF(OR($L16="",$M16<>"Active"),"",TODAY()-$L16) | Y16: =IF($M16<>"Active","",INDEX(Lists!$C$4:$C$14,MATCH($K16,Lists!$A$4:$A$14,0))) | Z16: =IF($B16="","",IF($M16<>"Active","Closed",IF($X16="","",IF($X16>$Y16,"BREACH","On Track")))) -> Closed | AA16: =IF($K16="","",IFERROR(INDEX(Lists!$E$4:$E$14,MATCH($K16,Lists!$A$4:$A$14,0)),"")) -> Send regret email | AB16: =IF($U16<>"",$U16,IF(OR($T16="",$M16<>"Active"),"",$T16+N($R16))) | AC16: =IF(OR($T16="",$J16=""),"",$T16-$J16) | AD16: =IF(AND($K16="Joined",$U16<>"",$J16<>""),$U16-$J16,"") | AE16: =IF($K16="","",IF(OR($K16="Rejected",$K16="Withdrawn"),IFERROR(INDEX(Lists!$B$4:$B$14,MATCH($N16,Lists!$A$4:$A$14,0)),1),IFERROR(INDEX(Lists!$B$4:$B$14,MATCH($K16,Lists!$A$4:$A$14,0)),0))) -> 1
A17: =IF($B17="","","C-"&TEXT(ROW()-1,"0000")) -> C-0016 | B17: Nisha Shah | C17: nisha.15@mail.com | D17: 9434848879 | E17: REQ-104 | F17: =IF($E17="","",IFERROR(INDEX(Requisitions!$B$2:$B$101,MATCH($E17,Requisitions!$A$2:$A$101,0)),"Unknown Req")) -> DevOps Engineer | G17: =IF($E17="","",IFERROR(INDEX(Requisitions!$D$2:$D$101,MATCH($E17,Requisitions!$A$2:$A$101,0)),"")) -> R. Nair | H17: LinkedIn | I17: Recruiter 3 | J17: 46247 | K17: Screening | L17: 46303 | M17: =IF($K17="","",IFERROR(INDEX(Lists!$D$4:$D$14,MATCH($K17,Lists!$A$4:$A$14,0)),"Check stage")) -> Active | O17: 2.9 | P17: 21.8 | Q17: 33.7 | R17: 90 | V17: =IF(OR(N($P17)=0,$Q17=""),"",$Q17/$P17-1) -> 0.54587156 | W17: =IF($J17="","",IF($M17="Active",TODAY(),IF($U17<>"",$U17,IF($L17<>"",$L17,TODAY())))-$J17) -> 63 | X17: =IF(OR($L17="",$M17<>"Active"),"",TODAY()-$L17) -> 7 | Y17: =IF($M17<>"Active","",INDEX(Lists!$C$4:$C$14,MATCH($K17,Lists!$A$4:$A$14,0))) -> 3 | Z17: =IF($B17="","",IF($M17<>"Active","Closed",IF($X17="","",IF($X17>$Y17,"BREACH","On Track")))) -> BREACH | AA17: =IF($K17="","",IFERROR(INDEX(Lists!$E$4:$E$14,MATCH($K17,Lists!$A$4:$A$14,0)),"")) -> Complete phone screen | AB17: =IF($U17<>"",$U17,IF(OR($T17="",$M17<>"Active"),"",$T17+N($R17))) | AC17: =IF(OR($T17="",$J17=""),"",$T17-$J17) | AD17: =IF(AND($K17="Joined",$U17<>"",$J17<>""),$U17-$J17,"") | AE17: =IF($K17="","",IF(OR($K17="Rejected",$K17="Withdrawn"),IFERROR(INDEX(Lists!$B$4:$B$14,MATCH($N17,Lists!$A$4:$A$14,0)),1),IFERROR(INDEX(Lists!$B$4:$B$14,MATCH($K17,Lists!$A$4:$A$14,0)),0))) -> 2
A18: =IF($B18="","","C-"&TEXT(ROW()-1,"0000")) -> C-0017 | B18: Gokul Nair | C18: gokul.16@mail.com | D18: 9257413274 | E18: REQ-105 | F18: =IF($E18="","",IFERROR(INDEX(Requisitions!$B$2:$B$101,MATCH($E18,Requisitions!$A$2:$A$101,0)),"Unknown Req")) -> Data Engineer | G18: =IF($E18="","",IFERROR(INDEX(Requisitions!$D$2:$D$101,MATCH($E18,Requisitions!$A$2:$A$101,0)),"")) -> P. Das | H18: Agency | I18: Recruiter 2 | J18: 46271 | K18: HR Round | L18: 46307 | M18: =IF($K18="","",IFERROR(INDEX(Lists!$D$4:$D$14,MATCH($K18,Lists!$A$4:$A$14,0)),"Check stage")) -> Active | O18: 8.1 | P18: 14.1 | Q18: 20.1 | R18: 15 | S18: 4 | V18: =IF(OR(N($P18)=0,$Q18=""),"",$Q18/$P18-1) -> 0.42553191 | W18: =IF($J18="","",IF($M18="Active",TODAY(),IF($U18<>"",$U18,IF($L18<>"",$L18,TODAY())))-$J18) -> 39 | X18: =IF(OR($L18="",$M18<>"Active"),"",TODAY()-$L18) -> 3 | Y18: =IF($M18<>"Active","",INDEX(Lists!$C$4:$C$14,MATCH($K18,Lists!$A$4:$A$14,0))) -> 3 | Z18: =IF($B18="","",IF($M18<>"Active","Closed",IF($X18="","",IF($X18>$Y18,"BREACH","On Track")))) -> On Track | AA18: =IF($K18="","",IFERROR(INDEX(Lists!$E$4:$E$14,MATCH($K18,Lists!$A$4:$A$14,0)),"")) -> HR discussion & salary alignment | AB18: =IF($U18<>"",$U18,IF(OR($T18="",$M18<>"Active"),"",$T18+N($R18))) | AC18: =IF(OR($T18="",$J18=""),"",$T18-$J18) | AD18: =IF(AND($K18="Joined",$U18<>"",$J18<>""),$U18-$J18,"") | AE18: =IF($K18="","",IF(OR($K18="Rejected",$K18="Withdrawn"),IFERROR(INDEX(Lists!$B$4:$B$14,MATCH($N18,Lists!$A$4:$A$14,0)),1),IFERROR(INDEX(Lists!$B$4:$B$14,MATCH($K18,Lists!$A$4:$A$14,0)),0))) -> 5
A19: =IF($B19="","","C-"&TEXT(ROW()-1,"0000")) -> C-0018 | B19: Lakshmi Patel | C19: lakshmi.17@mail.com | D19: 9493740901 | E19: REQ-106 | F19: =IF($E19="","",IFERROR(INDEX(Requisitions!$B$2:$B$101,MATCH($E19,Requisitions!$A$2:$A$101,0)),"Unknown Req")) -> Cloud Architect | G19: =IF($E19="","",IFERROR(INDEX(Requisitions!$D$2:$D$101,MATCH($E19,Requisitions!$A$2:$A$101,0)),"")) -> K. Menon | H19: Naukri | I19: Recruiter 3 | J19: 46305 | K19: Sourced | L19: 46306 | M19: =IF($K19="","",IFERROR(INDEX(Lists!$D$4:$D$14,MATCH($K19,Lists!$A$4:$A$14,0)),"Check stage")) -> Active | O19: 5.6 | P19: 10.3 | Q19: 14.5 | R19: 15 | V19: =IF(OR(N($P19)=0,$Q19=""),"",$Q19/$P19-1) -> 0.40776699 | W19: =IF($J19="","",IF($M19="Active",TODAY(),IF($U19<>"",$U19,IF($L19<>"",$L19,TODAY())))-$J19) -> 5 | X19: =IF(OR($L19="",$M19<>"Active"),"",TODAY()-$L19) -> 4 | Y19: =IF($M19<>"Active","",INDEX(Lists!$C$4:$C$14,MATCH($K19,Lists!$A$4:$A$14,0))) -> 3 | Z19: =IF($B19="","",IF($M19<>"Active","Closed",IF($X19="","",IF($X19>$Y19,"BREACH","On Track")))) -> BREACH | AA19: =IF($K19="","",IFERROR(INDEX(Lists!$E$4:$E$14,MATCH($K19,Lists!$A$4:$A$14,0)),"")) -> Reach out & share JD | AB19: =IF($U19<>"",$U19,IF(OR($T19="",$M19<>"Active"),"",$T19+N($R19))) | AC19: =IF(OR($T19="",$J19=""),"",$T19-$J19) | AD19: =IF(AND($K19="Joined",$U19<>"",$J19<>""),$U19-$J19,"") | AE19: =IF($K19="","",IF(OR($K19="Rejected",$K19="Withdrawn"),IFERROR(INDEX(Lists!$B$4:$B$14,MATCH($N19,Lists!$A$4:$A$14,0)),1),IFERROR(INDEX(Lists!$B$4:$B$14,MATCH($K19,Lists!$A$4:$A$14,0)),0))) -> 1
A20: =IF($B20="","","C-"&TEXT(ROW()-1,"0000")) -> C-0019 | B20: Hari Iyer | C20: hari.18@mail.com | D20: 9894432601 | E20: REQ-101 | F20: =IF($E20="","",IFERROR(INDEX(Requisitions!$B$2:$B$101,MATCH($E20,Requisitions!$A$2:$A$101,0)),"Unknown Req")) -> QA Automation Engineer (Python) | G20: =IF($E20="","",IFERROR(INDEX(Requisitions!$D$2:$D$101,MATCH($E20,Requisitions!$A$2:$A$101,0)),"")) -> S. Raman | H20: Naukri | I20: Pravin Christo | J20: 46209 | K20: Tech Round 1 | L20: 46307 | M20: =IF($K20="","",IFERROR(INDEX(Lists!$D$4:$D$14,MATCH($K20,Lists!$A$4:$A$14,0)),"Check stage")) -> Active | O20: 3.6 | P20: 15.4 | Q20: 20.8 | R20: 30 | S20: 3 | V20: =IF(OR(N($P20)=0,$Q20=""),"",$Q20/$P20-1) -> 0.35064935 | W20: =IF($J20="","",IF($M20="Active",TODAY(),IF($U20<>"",$U20,IF($L20<>"",$L20,TODAY())))-$J20) -> 101 | X20: =IF(OR($L20="",$M20<>"Active"),"",TODAY()-$L20) -> 3 | Y20: =IF($M20<>"Active","",INDEX(Lists!$C$4:$C$14,MATCH($K20,Lists!$A$4:$A$14,0))) -> 5 | Z20: =IF($B20="","",IF($M20<>"Active","Closed",IF($X20="","",IF($X20>$Y20,"BREACH","On Track")))) -> On Track | AA20: =IF($K20="","",IFERROR(INDEX(Lists!$E$4:$E$14,MATCH($K20,Lists!$A$4:$A$14,0)),"")) -> Schedule / collect Tech R1 feedback | AB20: =IF($U20<>"",$U20,IF(OR($T20="",$M20<>"Active"),"",$T20+N($R20))) | AC20: =IF(OR($T20="",$J20=""),"",$T20-$J20) | AD20: =IF(AND($K20="Joined",$U20<>"",$J20<>""),$U20-$J20,"") | AE20: =IF($K20="","",IF(OR($K20="Rejected",$K20="Withdrawn"),IFERROR(INDEX(Lists!$B$4:$B$14,MATCH($N20,Lists!$A$4:$A$14,0)),1),IFERROR(INDEX(Lists!$B$4:$B$14,MATCH($K20,Lists!$A$4:$A$14,0)),0))) -> 3
A21: =IF($B21="","","C-"&TEXT(ROW()-1,"0000")) -> C-0020 | B21: Pooja Das | C21: pooja.19@mail.com | D21: 9469668829 | E21: REQ-102 | F21: =IF($E21="","",IFERROR(INDEX(Requisitions!$B$2:$B$101,MATCH($E21,Requisitions!$A$2:$A$101,0)),"Unknown Req")) -> Senior SDET | G21: =IF($E21="","",IFERROR(INDEX(Requisitions!$D$2:$D$101,MATCH($E21,Requisitions!$A$2:$A$101,0)),"")) -> M. Iyer | H21: Career Page | I21: Pravin Christo | J21: 46214 | K21: Joined | L21: 46309 | M21: =IF($K21="","",IFERROR(INDEX(Lists!$D$4:$D$14,MATCH($K21,Lists!$A$4:$A$14,0)),"Check stage")) -> Hired | O21: 11.5 | P21: 24.8 | Q21: 36.4 | R21: 90 | S21: 5 | T21: 46240 | U21: 46309 | V21: =IF(OR(N($P21)=0,$Q21=""),"",$Q21/$P21-1) -> 0.46774194 | W21: =IF($J21="","",IF($M21="Active",TODAY(),IF($U21<>"",$U21,IF($L21<>"",$L21,TODAY())))-$J21) -> 95 | X21: =IF(OR($L21="",$M21<>"Active"),"",TODAY()-$L21) | Y21: =IF($M21<>"Active","",INDEX(Lists!$C$4:$C$14,MATCH($K21,Lists!$A$4:$A$14,0))) | Z21: =IF($B21="","",IF($M21<>"Active","Closed",IF($X21="","",IF($X21>$Y21,"BREACH","On Track")))) -> Closed | AA21: =IF($K21="","",IFERROR(INDEX(Lists!$E$4:$E$14,MATCH($K21,Lists!$A$4:$A$14,0)),"")) -> Onboarding complete | AB21: =IF($U21<>"",$U21,IF(OR($T21="",$M21<>"Active"),"",$T21+N($R21))) -> 46309 | AC21: =IF(OR($T21="",$J21=""),"",$T21-$J21) -> 26 | AD21: =IF(AND($K21="Joined",$U21<>"",$J21<>""),$U21-$J21,"") -> 95 | AE21: =IF($K21="","",IF(OR($K21="Rejected",$K21="Withdrawn"),IFERROR(INDEX(Lists!$B$4:$B$14,MATCH($N21,Lists!$A$4:$A$14,0)),1),IFERROR(INDEX(Lists!$B$4:$B$14,MATCH($K21,Lists!$A$4:$A$14,0)),0))) -> 8
A22: =IF($B22="","","C-"&TEXT(ROW()-1,"0000")) -> C-0021 | B22: Naveen Shah | C22: naveen.20@mail.com | D22: 9770086184 | E22: REQ-103 | F22: =IF($E22="","",IFERROR(INDEX(Requisitions!$B$2:$B$101,MATCH($E22,Requisitions!$A$2:$A$101,0)),"Unknown Req")) -> Python Backend Developer | G22: =IF($E22="","",IFERROR(INDEX(Requisitions!$D$2:$D$101,MATCH($E22,Requisitions!$A$2:$A$101,0)),"")) -> A. Kumar | H22: Indeed | I22: Recruiter 2 | J22: 46247 | K22: Offered | L22: 46271 | M22: =IF($K22="","",IFERROR(INDEX(Lists!$D$4:$D$14,MATCH($K22,Lists!$A$4:$A$14,0)),"Check stage")) -> Active | O22: 11.9 | P22: 5.7 | Q22: 6.8 | R22: 90 | S22: 3 | T22: 46271 | V22: =IF(OR(N($P22)=0,$Q22=""),"",$Q22/$P22-1) -> 0.19298246 | W22: =IF($J22="","",IF($M22="Active",TODAY(),IF($U22<>"",$U22,IF($L22<>"",$L22,TODAY())))-$J22) -> 63 | X22: =IF(OR($L22="",$M22<>"Active"),"",TODAY()-$L22) -> 39 | Y22: =IF($M22<>"Active","",INDEX(Lists!$C$4:$C$14,MATCH($K22,Lists!$A$4:$A$14,0))) -> 5 | Z22: =IF($B22="","",IF($M22<>"Active","Closed",IF($X22="","",IF($X22>$Y22,"BREACH","On Track")))) -> BREACH | AA22: =IF($K22="","",IFERROR(INDEX(Lists!$E$4:$E$14,MATCH($K22,Lists!$A$4:$A$14,0)),"")) -> Follow up on offer acceptance | AB22: =IF($U22<>"",$U22,IF(OR($T22="",$M22<>"Active"),"",$T22+N($R22))) -> 46361 | AC22: =IF(OR($T22="",$J22=""),"",$T22-$J22) -> 24 | AD22: =IF(AND($K22="Joined",$U22<>"",$J22<>""),$U22-$J22,"") | AE22: =IF($K22="","",IF(OR($K22="Rejected",$K22="Withdrawn"),IFERROR(INDEX(Lists!$B$4:$B$14,MATCH($N22,Lists!$A$4:$A$14,0)),1),IFERROR(INDEX(Lists!$B$4:$B$14,MATCH($K22,Lists!$A$4:$A$14,0)),0))) -> 6
